Workbook
Name fase: Lookup!#REF!
Name volwassenheid_stelsel: Lookup!#REF!

Sheet Werkzaamheden
C1: Vul de geel gemarkeerde velden in, verwijder daarna deze tekst. Vul de uurtarief in in het tabblad Lookup
F3: Totaal aantal uren | J3: Totaal excl BTW | K3: Totaal incl BTW
C4: NAAM (OFFERTE) opdracht beheer afsprakenstelsel | H4: =SUM(H11:H98) -> 0 | J4: =SUM(J10,J33,J59,J74,J88,J100)*M5 -> 0 | K4: =J4*1.21 -> 0
C5: Is het een nieuw, beginnend, volwassen of een stelsel in uitfasering? | H5: Nieuw | M5: =VLOOKUP(Werkzaamheden!H5,Lookup!B9:C12,2,FALSE) -> 1.3
N8: Toelichting
J9: Bedrag | N9: WpJ | O9: Weken per jaar
B10: 1 | C10: Strategie | E10: WpJ | F10: UpW | G10: Tar | H10: Uren | J10: =SUM(K11:K31) -> 0 | N10: UpW | O10: Uren per week
B11: 1.1 | C11: Governance | N11: Bijvoorbeeld
C12: Secretariaatsvoering en faciliteren van overleggremia | H12: =E12*F12 -> 0 | K12: =IF(H12=0, 0, _xlfn.IFNA(H12*LOOKUP(G12,Lookup!$B$3:$B$6,Lookup!$C$3:$C$6), 0)) -> 0 | N12: 52 WpJ/ 16 UpW | O12: structureel werk wat twee werkdagen per week kost
C13: Communicatieondersteuning voor governance | H13: =E13*F13 -> 0 | K13: =IF(H13=0, 0, _xlfn.IFNA(H13*LOOKUP(G13,Lookup!$B$3:$B$6,Lookup!$C$3:$C$6), 0)) -> 0 | N13: 4 WpJ/ 8 UpW | O13: ieder kwartaal een dag voor dit onderwerp
C14: Planning en coördinatie | H14: =E14*F14 -> 0 | K14: =IF(H14=0, 0, _xlfn.IFNA(H14*LOOKUP(G14,Lookup!$B$3:$B$6,Lookup!$C$3:$C$6), 0)) -> 0
C15: Informatievoorziening en rapportage | H15: =E15*F15 -> 0 | K15: =IF(H15=0, 0, _xlfn.IFNA(H15*LOOKUP(G15,Lookup!$B$3:$B$6,Lookup!$C$3:$C$6), 0)) -> 0 | N15: Tar | O15: tarief
B16: 1.2 | C16: Visie | H16: =E16*F16 -> 0 | K16: =IF(H16=0, 0, _xlfn.IFNA(H16*LOOKUP(G16,Lookup!$B$3:$B$6,Lookup!$C$3:$C$6), 0)) -> 0 | N16: H | O16: Hoog
C17: Ondersteuning van visie- en strategievorming | H17: =E17*F17 -> 0 | K17: =IF(H17=0, 0, _xlfn.IFNA(H17*LOOKUP(G17,Lookup!$B$3:$B$6,Lookup!$C$3:$C$6), 0)) -> 0 | N17: M | O17: midden
C18: Ontwikkelen en onderhouden van visiedocumenten | H18: =E18*F18 -> 0 | K18: =IF(H18=0, 0, _xlfn.IFNA(H18*LOOKUP(G18,Lookup!$B$3:$B$6,Lookup!$C$3:$C$6), 0)) -> 0 | N18: L | O18: laag
C19: Signaleren en analyseren van relevante ontwikkelingen | H19: =E19*F19 -> 0 | K19: =IF(H19=0, 0, _xlfn.IFNA(H19*LOOKUP(G19,Lookup!$B$3:$B$6,Lookup!$C$3:$C$6), 0)) -> 0 | N19: Bijvoorbeeld
B20: 1.3 | C20: Financiën | H20: =E20*F20 -> 0 | K20: =IF(H20=0, 0, _xlfn.IFNA(H20*LOOKUP(G20,Lookup!$B$3:$B$6,Lookup!$C$3:$C$6), 0)) -> 0 | N20: Tar H
C21: Ontwikkelen en onderhouden van financiële modellen | H21: =E21*F21 -> 0 | K21: =IF(H21=0, 0, _xlfn.IFNA(H21*LOOKUP(G21,Lookup!$B$3:$B$6,Lookup!$C$3:$C$6), 0)) -> 0 | N21: H is tarief van een senior adviseur (zie waarde in tabblad Lookup)
C22: Financiële rapportage en verantwoording | H22: =E22*F22 -> 0 | K22: =IF(H22=0, 0, _xlfn.IFNA(H22*LOOKUP(G22,Lookup!$B$3:$B$6,Lookup!$C$3:$C$6), 0)) -> 0
C23: Opstellen jaarplan /begroting | H23: =E23*F23 -> 0 | K23: =IF(H23=0, 0, _xlfn.IFNA(H23*LOOKUP(G23,Lookup!$B$3:$B$6,Lookup!$C$3:$C$6), 0)) -> 0
B24: 1.4 | C24: Toezicht | H24: =E24*F24 -> 0 | K24: =IF(H24=0, 0, _xlfn.IFNA(H24*LOOKUP(G24,Lookup!$B$3:$B$6,Lookup!$C$3:$C$6), 0)) -> 0
C25: Bewaken van stelselneutraliteit en -integriteit | H25: =E25*F25 -> 0 | K25: =IF(H25=0, 0, _xlfn.IFNA(H25*LOOKUP(G25,Lookup!$B$3:$B$6,Lookup!$C$3:$C$6), 0)) -> 0
C26: Onderhouden contact toezichthouder | H26: =E26*F26 -> 0 | K26: =IF(H26=0, 0, _xlfn.IFNA(H26*LOOKUP(G26,Lookup!$B$3:$B$6,Lookup!$C$3:$C$6), 0)) -> 0
C27: Faciliteren van toetredingsprocessen | H27: =E27*F27 -> 0 | K27: =IF(H27=0, 0, _xlfn.IFNA(H27*LOOKUP(G27,Lookup!$B$3:$B$6,Lookup!$C$3:$C$6), 0)) -> 0
B28: 1.5 | C28: Businesscase | H28: =E28*F28 -> 0 | K28: =IF(H28=0, 0, _xlfn.IFNA(H28*LOOKUP(G28,Lookup!$B$3:$B$6,Lookup!$C$3:$C$6), 0)) -> 0
C29: Periodieke herijking van de businesscase | H29: =E29*F29 -> 0 | K29: =IF(H29=0, 0, _xlfn.IFNA(H29*LOOKUP(G29,Lookup!$B$3:$B$6,Lookup!$C$3:$C$6), 0)) -> 0
C30: Initiële ontwikkeling en onderbouwing van de businesscase | H30: =E30*F30 -> 0 | K30: =IF(H30=0, 0, _xlfn.IFNA(H30*LOOKUP(G30,Lookup!$B$3:$B$6,Lookup!$C$3:$C$6), 0)) -> 0
C31: Communiceren over de waarde van het stelsel | H31: =E31*F31 -> 0 | K31: =IF(H31=0, 0, _xlfn.IFNA(H31*LOOKUP(G31,Lookup!$B$3:$B$6,Lookup!$C$3:$C$6), 0)) -> 0
B33: 2 | C33: Tactiek | E33: WpJ | F33: UpW | G33: Tar | H33: Uren | J33: =SUM(K34:K57) -> 0
B34: 2.1 | C34: Werkgroepen | H34: =E34*F34 -> 0 | K34: =IF(H34=0, 0, _xlfn.IFNA(H34*LOOKUP(G34,Lookup!$B$3:$B$6,Lookup!$C$3:$C$6), 0)) -> 0
C35: Voorzitten, voorbereiden en ondersteuning werkgroepen | H35: =E35*F35 -> 0 | K35: =IF(H35=0, 0, _xlfn.IFNA(H35*LOOKUP(G35,Lookup!$B$3:$B$6,Lookup!$C$3:$C$6), 0)) -> 0
C36: Inrichten en onderhouden (werkgroep)kennis deel platform | H36: =E36*F36 -> 0 | K36: =IF(H36=0, 0, _xlfn.IFNA(H36*LOOKUP(G36,Lookup!$B$3:$B$6,Lookup!$C$3:$C$6), 0)) -> 0
C37: Stimuleren van actieve participatie | H37: =E37*F37 -> 0 | K37: =IF(H37=0, 0, _xlfn.IFNA(H37*LOOKUP(G37,Lookup!$B$3:$B$6,Lookup!$C$3:$C$6), 0)) -> 0
C38: Organiseren van rapportage over resultaten | H38: =E38*F38 -> 0 | K38: =IF(H38=0, 0, _xlfn.IFNA(H38*LOOKUP(G38,Lookup!$B$3:$B$6,Lookup!$C$3:$C$6), 0)) -> 0
C39: Werven en behouden van relevante stakeholders | H39: =E39*F39 -> 0 | K39: =IF(H39=0, 0, _xlfn.IFNA(H39*LOOKUP(G39,Lookup!$B$3:$B$6,Lookup!$C$3:$C$6), 0)) -> 0
B40: 2.2 | C40: Architectuur | H40: =E40*F40 -> 0 | K40: =IF(H40=0, 0, _xlfn.IFNA(H40*LOOKUP(G40,Lookup!$B$3:$B$6,Lookup!$C$3:$C$6), 0)) -> 0
C41: In kaart brengen en beheren van relaties met andere stelsels/standaarden | H41: =E41*F41 -> 0 | K41: =IF(H41=0, 0, _xlfn.IFNA(H41*LOOKUP(G41,Lookup!$B$3:$B$6,Lookup!$C$3:$C$6), 0)) -> 0
C42: Maken / bijhouden en uitleg geven architectuur | H42: =E42*F42 -> 0 | K42: =IF(H42=0, 0, _xlfn.IFNA(H42*LOOKUP(G42,Lookup!$B$3:$B$6,Lookup!$C$3:$C$6), 0)) -> 0
C43: Organiseren van afstemming met overige stelsels en standaarden | H43: =E43*F43 -> 0 | K43: =IF(H43=0, 0, _xlfn.IFNA(H43*LOOKUP(G43,Lookup!$B$3:$B$6,Lookup!$C$3:$C$6), 0)) -> 0
C44: Monitoren van relevante internationale ontwikkelingen | H44: =E44*F44 -> 0 | K44: =IF(H44=0, 0, _xlfn.IFNA(H44*LOOKUP(G44,Lookup!$B$3:$B$6,Lookup!$C$3:$C$6), 0)) -> 0
...

Sheet Lookup
A2: # | B2: Tariefsoort | C2: Uurtarieven 2025
A3: 1 | B3: H | C3: 110
A4: 2 | B4: L | C4: 85
A5: 3 | B5: M | C5: 95
A6: 4
B8: Fase volwassenheid | C8: Factor
B9: Nieuw | C9: 1.3
B10: In ontwikkeling | C10: 1.2
B11: Volwassen | C11: 0.9
B12: Uitfaseren | C12: 0.7
